#VRML_SIM R2019a utf8
WorldInfo {
}
Viewpoint {
  orientation 0.09142355111504703 -0.9828551861031887 -0.16011688684077313 4.202840629438026
  position 3.482263448851523 2.5981513975930586 -2.232710273248825
  follow "floor"
  followOrientation TRUE
}
TexturedBackground {
}
TexturedBackgroundLight {
}
Floor {
}
DEF U_D_WALLS Solid {
  translation 0 0.025 0.019999999999999945
  children [
    Group {
      children [
        Solid {
          children [
            Shape {
              appearance PBRAppearance {
                baseColor 0.4470588235294118 0.6235294117647059 0.8117647058823529
              }
              geometry DEF G_BASE_BOX Box {
                size 1 0.05 1
              }
            }
          ]
          boundingObject USE G_BASE_BOX
        }
        Transform {
          translation 0 0.95 0
          children [
            Shape {
              appearance PBRAppearance {
                baseColor 0.4470588235294118 0.6235294117647059 0.8117647058823529
              }
              geometry USE G_BASE_BOX
            }
          ]
        }
      ]
    }
  ]
  boundingObject USE G_BASE_BOX
}
DEF SIDE_WALLS Solid {
  translation 0.301 0.314 0.005000000000000022
  children [
    Group {
      children [
        Solid {
          translation 0.14999993342509008 0.1882842702403733 0.48000006657491023
          rotation -0.5773502774946302 -0.5773502664212908 -0.5773502636529562 4.188790221396401
          children [
            Shape {
              appearance DEF GREEN_BAR PBRAppearance {
                baseColor 0.5411764705882353 0.8862745098039215 0.20392156862745098
              }
              geometry DEF G_WALL_BAR Box {
                size 0.9 0.05 0.1
              }
            }
          ]
          boundingObject USE G_WALL_BAR
        }
        Transform {
          translation -0.3000000000000001 -0.2199999999520511 0.48000000105487756
          rotation 1 0 0 1.5707963220000003
          children [
            Shape {
              appearance PBRAppearance {
                baseColor 0.5411764705882353 0.8862745098039215 0.20392156862745098
              }
              geometry Box {
                size 1 0.05 0.1
              }
            }
          ]
        }
        Transform {
          translation -0.3000000000000001 0.5900000000479493 0.4799999971710106
          rotation 1 0 0 1.5707963220000003
          children [
            Shape {
              appearance PBRAppearance {
                baseColor 0.5411764705882353 0.8862745098039215 0.20392156862745098
              }
              geometry Box {
                size 1 0.05 0.1
              }
            }
          ]
        }
        Transform {
          translation -0.7499999992328169 0.188 0.4799999999520512
          rotation 0.577350270112404 0.5773502673440692 0.577350270112404 2.094395096856526
          children [
            Shape {
              appearance PBRAppearance {
                baseColor 0.5411764705882353 0.8862745098039215 0.20392156862745098
              }
              geometry USE G_WALL_BAR
            }
          ]
        }
        Transform {
          translation -0.32737176735104395 0.167683152275373 0.48000001372671436
          rotation -0.8628561829522664 -0.3574067771923322 -0.3574067754786351 4.565415021643904
          children [
            Shape {
              appearance PBRAppearance {
                baseColor 0.5411764705882353 0.8862745098039215 0.20392156862745098
              }
              geometry Box {
                size 1.1967 0.05 0.07
              }
            }
          ]
        }
        Transform {
          translation -0.29707106801796274 0.1787868014454837 0.48000001524394903
          rotation -0.28108447794031916 -0.6785986842687024 -0.6785980710035978 3.6896218982461395
          children [
            Shape {
              appearance PBRAppearance {
                baseColor 0.5411764705882353 0.8862745098039215 0.20392156862745098
              }
              geometry Box {
                size 1.3142 0.05 0.07
              }
            }
          ]
        }
        Transform {
          translation -3.469446951953614e-18 0 -0.9400000000000005
          children [
            Group {
              children [
                Solid {
                  translation 0.14999993342509008 0.1882842702403733 0.48000006657491023
                  rotation -0.5773502774946302 -0.5773502664212908 -0.5773502636529562 4.188790221396401
                  children [
                    Shape {
                      appearance PBRAppearance {
                        baseColor 0.5411764705882353 0.8862745098039215 0.20392156862745098
                      }
                      geometry DEF G_WALL_BAR Box {
                        size 0.9 0.05 0.1
                      }
                    }
                  ]
                  name "solid(1)"
                  boundingObject USE G_WALL_BAR
                }
                Transform {
                  translation -0.3000000000000001 -0.2199999999520511 0.48000000105487756
                  rotation 1 0 0 1.5707963220000003
                  children [
                    Shape {
                      appearance PBRAppearance {
                        baseColor 0.5411764705882353 0.8862745098039215 0.20392156862745098
                      }
                      geometry Box {
                        size 1 0.05 0.1
                      }
                    }
                  ]
                }
                Transform {
                  translation -0.3000000000000001 0.5900000000479493 0.4799999971710106
                  rotation 1 0 0 1.5707963220000003
                  children [
                    Shape {
                      appearance PBRAppearance {
                        baseColor 0.5411764705882353 0.8862745098039215 0.20392156862745098
                      }
                      geometry Box {
                        size 1 0.05 0.1
                      }
                    }
                  ]
                }
                Transform {
                  translation -0.7499999992328169 0.188 0.4799999999520512
                  rotation 0.577350270112404 0.5773502673440692 0.577350270112404 2.094395096856526
                  children [
                    Shape {
                      appearance PBRAppearance {
                        baseColor 0.5411764705882353 0.8862745098039215 0.20392156862745098
                      }
                      geometry USE G_WALL_BAR
                    }
                  ]
                }
                Transform {
                  translation -0.32737176735104395 0.167683152275373 0.48000001372671436
                  rotation -0.8628561829522664 -0.3574067771923322 -0.3574067754786351 4.565415021643904
                  children [
                    Shape {
                      appearance PBRAppearance {
                        baseColor 0.5411764705882353 0.8862745098039215 0.20392156862745098
                      }
                      geometry Box {
                        size 1.1967 0.05 0.07
                      }
                    }
                  ]
                }
                Transform {
                  translation -0.29707106801796274 0.1787868014454837 0.48000001524394903
                  rotation -0.28108447794031916 -0.6785986842687024 -0.6785980710035978 3.6896218982461395
                  children [
                    Shape {
                      appearance PBRAppearance {
                        baseColor 0.5411764705882353 0.8862745098039215 0.20392156862745098
                      }
                      geometry Box {
                        size 1.3142 0.05 0.07
                      }
                    }
                  ]
                }
              ]
            }
          ]
        }
        Transform {
          translation -0.31000000086308127 0 -0.290000001486417
          rotation 0 1 0 1.5707963220000003
          children [
            Group {
              children [
                Solid {
                  translation 0.14999993342509008 0.1882842702403733 0.48000006657491023
                  rotation -0.5773502774946302 -0.5773502664212908 -0.5773502636529562 4.188790221396401
                  children [
                    Shape {
                      appearance PBRAppearance {
                        baseColor 0.5411764705882353 0.8862745098039215 0.20392156862745098
                      }
                      geometry DEF G_WALL_BAR Box {
                        size 0.9 0.05 0.1
                      }
                    }
                  ]
                  name "solid(2)"
                  boundingObject USE G_WALL_BAR
                }
                Transform {
                  translation -0.3000000000000001 -0.2199999999520511 0.48000000105487756
                  rotation 1 0 0 1.5707963220000003
                  children [
                    Shape {
                      appearance PBRAppearance {
                        baseColor 0.5411764705882353 0.8862745098039215 0.20392156862745098
                      }
                      geometry Box {
                        size 1 0.05 0.1
                      }
                    }
                  ]
                }
                Transform {
                  translation -0.3000000000000001 0.5900000000479493 0.4799999971710106
                  rotation 1 0 0 1.5707963220000003
                  children [
                    Shape {
                      appearance PBRAppearance {
                        baseColor 0.5411764705882353 0.8862745098039215 0.20392156862745098
                      }
                      geometry Box {
                        size 1 0.05 0.1
                      }
                    }
                  ]
                }
                Transform {
                  translation -0.7499999992328169 0.188 0.4799999999520512
                  rotation 0.577350270112404 0.5773502673440692 0.577350270112404 2.094395096856526
                  children [
                    Shape {
                      appearance PBRAppearance {
                        baseColor 0.5411764705882353 0.8862745098039215 0.20392156862745098
                      }
                      geometry USE G_WALL_BAR
                    }
                  ]
                }
                Transform {
                  translation -0.32737176735104395 0.167683152275373 0.48000001372671436
                  rotation -0.8628561829522664 -0.3574067771923322 -0.3574067754786351 4.565415021643904
                  children [
                    Shape {
                      appearance PBRAppearance {
                        baseColor 0.5411764705882353 0.8862745098039215 0.20392156862745098
                      }
                      geometry Box {
                        size 1.1967 0.05 0.07
                      }
                    }
                  ]
                }
                Transform {
                  translation -0.29707106801796274 0.1787868014454837 0.48000001524394903
                  rotation -0.28108447794031916 -0.6785986842687024 -0.6785980710035978 3.6896218982461395
                  children [
                    Shape {
                      appearance PBRAppearance {
                        baseColor 0.5411764705882353 0.8862745098039215 0.20392156862745098
                      }
                      geometry Box {
                        size 1.3142 0.05 0.07
                      }
                    }
                  ]
                }
              ]
            }
          ]
        }
        Transform {
          translation -0.2900000044592544 0 0.3100000089185083
          rotation 0 0.9999999999999999 0 4.712388966
          children [
            Group {
              children [
                Solid {
                  translation 0.14999993342509008 0.1882842702403733 0.48000006657491023
                  rotation -0.5773502774946302 -0.5773502664212908 -0.5773502636529562 4.188790221396401
                  children [
                    Shape {
                      appearance PBRAppearance {
                        baseColor 0.5411764705882353 0.8862745098039215 0.20392156862745098
                      }
                      geometry DEF G_WALL_BAR Box {
                        size 0.9 0.05 0.1
                      }
                    }
                  ]
                  name "solid(3)"
                  boundingObject USE G_WALL_BAR
                }
                Transform {
                  translation -0.3000000000000001 -0.2199999999520511 0.48000000105487756
                  rotation 1 0 0 1.5707963220000003
                  children [
                    Shape {
                      appearance PBRAppearance {
                        baseColor 0.5411764705882353 0.8862745098039215 0.20392156862745098
                      }
                      geometry Box {
                        size 1 0.05 0.1
                      }
                    }
                  ]
                }
                Transform {
                  translation -0.3000000000000001 0.5900000000479493 0.4799999971710106
                  rotation 1 0 0 1.5707963220000003
                  children [
                    Shape {
                      appearance PBRAppearance {
                        baseColor 0.5411764705882353 0.8862745098039215 0.20392156862745098
                      }
                      geometry Box {
                        size 1 0.05 0.1
                      }
                    }
                  ]
                }
                Transform {
                  translation -0.7499999992328169 0.188 0.4799999999520512
                  rotation 0.577350270112404 0.5773502673440692 0.577350270112404 2.094395096856526
                  children [
                    Shape {
                      appearance PBRAppearance {
                        baseColor 0.5411764705882353 0.8862745098039215 0.20392156862745098
                      }
                      geometry USE G_WALL_BAR
                    }
                  ]
                }
                Transform {
                  translation -0.32737176735104395 0.167683152275373 0.48000001372671436
                  rotation -0.8628561829522664 -0.3574067771923322 -0.3574067754786351 4.565415021643904
                  children [
                    Shape {
                      appearance PBRAppearance {
                        baseColor 0.5411764705882353 0.8862745098039215 0.20392156862745098
                      }
                      geometry Box {
                        size 1.1967 0.05 0.07
                      }
                    }
                  ]
                }
                Transform {
                  translation -0.29707106801796274 0.1787868014454837 0.48000001524394903
                  rotation -0.28108447794031916 -0.6785986842687024 -0.6785980710035978 3.6896218982461395
                  children [
                    Shape {
                      appearance PBRAppearance {
                        baseColor 0.5411764705882353 0.8862745098039215 0.20392156862745098
                      }
                      geometry Box {
                        size 1.3142 0.05 0.07
                      }
                    }
                  ]
                }
              ]
            }
          ]
        }
      ]
    }
  ]
  name "solid(1)"
  boundingObject USE G_WALL_BAR
}
Solid {
  children [
    Group {
      children [
        DEF G_CYLINDER Solid {
          translation 0 1.5 0
          children [
            Shape {
              appearance DEF HELIX PBRAppearance {
                baseColor 0.9882352941176471 0.6862745098039216 0.24313725490196078
              }
              geometry DEF G_CYLINDER_HELX Cylinder {
                height 1
                radius 0.1
              }
            }
          ]
        }
        HingeJoint {
          jointParameters HingeJointParameters {
            axis 0 1 0
            anchor 0 1 0
            staticFriction 0.02
          }
          endPoint Solid {
            translation 0.25000000000000006 2.049999998801279 0
            rotation 0 0 1 1.5707963220000003
            children [
              Shape {
                appearance USE HELIX
                geometry DEF G_HELIX_BAR Cylinder {
                  height 1
                  radius 0.05
                }
              }
              HingeJoint {
                jointParameters HingeJointParameters {
                  axis 0 1 0
                  staticFriction 0.01
                }
                endPoint Solid {
                  translation 0 -0.5 0
                  rotation 1 0 0 1.5707963220000003
                  children [
                    DEF HELIX Group {
                      children [
                        Solid {
                          children [
                            Shape {
                              appearance PBRAppearance {
                                baseColor 0.9882352941176471 0.6862745098039216 0.24313725490196078
                              }
                              geometry DEF G_HELIX Box {
                                size 0.9 0.1 0.05
                              }
                            }
                          ]
                          boundingObject USE G_HELIX
                          physics Physics {
                          }
                        }
                        Transform {
                          rotation 0 0 1 1.5707996938995747
                          children [
                            Shape {
                              appearance PBRAppearance {
                                baseColor 0.9882352941176471 0.6862745098039216 0.24313725490196078
                              }
                              geometry USE G_HELIX
                            }
                          ]
                        }
                      ]
                    }
                  ]
                  boundingObject USE G_HELIX
                  physics Physics {
                  }
                }
              }
            ]
            name "solid(1)"
            boundingObject USE G_HELIX_BAR
            physics Physics {
            }
          }
        }
      ]
    }
  ]
  name "solid(2)"
}
